<?xml version="1.0" ?>
<robot name="robotiq_85_gripper">
  <link name="robotiq_85_base_link">
    <visual>
      <geometry>
        <mesh filename="../meshes/visual/robotiq_85_base_link.obj"/>
      </geometry>
    </visual>
    <collision>
      <geometry>
        <mesh filename="../meshes/collision/robotiq_85_base_link.obj"/>
      </geometry>
    </collision>
    <inertial>
      <mass value="0.636951"/>
      <origin xyz="0.0 0.0 0.0"/>
      <inertia ixx="0.000380" ixy="0.000000" ixz="0.000000" iyx="0.000000" iyy="0.001110" iyz="0.000000" izx="0.000000" izy="0.000000" izz="0.001171"/>
    </inertial>
  </link>
  <joint name="robotiq_85_left_knuckle_joint" type="revolute">
    <parent link="robotiq_85_base_link"/>
    <child link="robotiq_85_left_knuckle_link"/>
    <axis xyz="0 0 1"/>
    <origin rpy="3.141592653589793 0.0 0.0" xyz="0.05490451627 0.03060114443 0.0"/>
    <limit effort="1000" lower="0.0" upper="0.80285" velocity="0.5"/>
  </joint>
  <joint name="robotiq_85_right_knuckle_joint" type="continuous">
    <parent link="robotiq_85_base_link"/>
    <child link="robotiq_85_right_knuckle_link"/>
    <axis xyz="0 0 1"/>
    <origin rpy="0.0 0.0 0.0" xyz="0.05490451627 -0.03060114443 0.0"/>
    <limit effort="1000" lower="-3.14" upper="3.14" velocity="100.0"/>
    <mimic joint="robotiq_85_left_knuckle_joint"/>
  </joint>
  <link name="robotiq_85_left_knuckle_link">
    <visual>
      <geometry>
        <mesh filename="../meshes/visual/robotiq_85_knuckle_link.obj"/>
      </geometry>
    </visual>
    <collision>
      <geometry>
        <mesh filename="../meshes/collision/robotiq_85_knuckle_link.obj"/>
      </geometry>
    </collision>
    <inertial>
      <mass value="0.018491"/>
      <origin xyz="0.0 0.0 0.0"/>
      <inertia ixx="0.000009" ixy="-0.000001" ixz="0.000000" iyx="-0.000001" iyy="0.000001" iyz="0.000000" izx="0.000000" izy="0.000000" izz="0.000010"/>
    </inertial>
  </link>
  <link name="robotiq_85_right_knuckle_link">
    <visual>
      <geometry>
        <mesh filename="../meshes/visual/robotiq_85_knuckle_link.obj"/>
      </geometry>
    </visual>
    <collision>
      <geometry>
        <mesh filename="../meshes/collision/robotiq_85_knuckle_link.obj"/>
      </geometry>
    </collision>
    <inertial>
      <mass value="0.018491"/>
      <origin xyz="0.0 0.0 0.0"/>
      <inertia ixx="0.000009" ixy="-0.000001" ixz="0.000000" iyx="-0.000001" iyy="0.000001" iyz="0.000000" izx="0.000000" izy="0.000000" izz="0.000010"/>
    </inertial>
  </link>
  <joint name="robotiq_85_left_finger_joint" type="fixed">
    <parent link="robotiq_85_left_knuckle_link"/>
    <child link="robotiq_85_left_finger_link"/>
    <origin rpy="0 0 0" xyz="-0.00408552455 -0.03148604435 0.0"/>
  </joint>
  <joint name="robotiq_85_right_finger_joint" type="fixed">
    <parent link="robotiq_85_right_knuckle_link"/>
    <child link="robotiq_85_right_finger_link"/>
    <origin rpy="0 0 0" xyz="-0.00408552455 -0.03148604435 0.0"/>
  </joint>
  <link name="robotiq_85_left_finger_link">
    <visual>
      <geometry>
        <mesh filename="../meshes/visual/robotiq_85_finger_link.obj"/>
      </geometry>
    </visual>
    <collision>
      <geometry>
        <mesh filename="../meshes/collision/robotiq_85_finger_link.obj"/>
      </geometry>
    </collision>
    <inertial>
      <mass value="0.027309"/>
      <origin xyz="0.0 0.0 0.0"/>
      <inertia ixx="0.000003" ixy="-0.000002" ixz="0.000000" iyx="-0.000002" iyy="0.000021" iyz="0.000000" izx="0.000000" izy="0.000000" izz="0.000020"/>
    </inertial>
  </link>
  <link name="robotiq_85_right_finger_link">
    <visual>
      <geometry>
        <mesh filename="../meshes/visual/robotiq_85_finger_link.obj"/>
      </geometry>
    </visual>
    <collision>
      <geometry>
        <mesh filename="../meshes/collision/robotiq_85_finger_link.obj"/>
      </geometry>
    </collision>
    <inertial>
      <mass value="0.027309"/>
      <origin xyz="0.0 0.0 0.0"/>
      <inertia ixx="0.000003" ixy="-0.000002" ixz="0.000000" iyx="-0.000002" iyy="0.000021" iyz="0.000000" izx="0.000000" izy="0.000000" izz="0.000020"/>
    </inertial>
  </link>
  <joint name="robotiq_85_left_inner_knuckle_joint" type="continuous">
    <parent link="robotiq_85_base_link"/>
    <child link="robotiq_85_left_inner_knuckle_link"/>
    <axis xyz="0 0 1"/>
    <origin rpy="3.141592653589793 0.0 0.0" xyz="0.06142 0.0127 0"/>
    <limit effort="0.1" lower="-3.14" upper="3.14" velocity="100.0"/>
    <mimic joint="robotiq_85_left_knuckle_joint" offset="0"/>
  </joint>
  <joint name="robotiq_85_right_inner_knuckle_joint" type="continuous">
    <parent link="robotiq_85_base_link"/>
    <child link="robotiq_85_right_inner_knuckle_link"/>
    <axis xyz="0 0 1"/>
    <origin rpy="0 0 0" xyz="0.06142 -0.0127 0"/>
    <limit effort="0.1" lower="-3.14" upper="3.14" velocity="100.0"/>
    <mimic joint="robotiq_85_left_knuckle_joint" offset="0"/>
  </joint>
  <link name="robotiq_85_left_inner_knuckle_link">
    <visual>
      <geometry>
        <mesh filename="../meshes/visual/robotiq_85_inner_knuckle_link.obj"/>
      </geometry>
    </visual>
    <collision>
      <geometry>
        <mesh filename="../meshes/collision/robotiq_85_inner_knuckle_link.obj"/>
      </geometry>
    </collision>
    <inertial>
      <mass value="0.029951"/>
      <origin xyz="0.0 0.0 0.0"/>
      <inertia ixx="0.000039" ixy="0.000000" ixz="0.000000" iyx="0.000000" iyy="0.000005" iyz="0.000000" izx="0.000000" izy="0.000000" izz="0.000035"/>
    </inertial>
  </link>
  <link name="robotiq_85_right_inner_knuckle_link">
    <visual>
      <geometry>
        <mesh filename="../meshes/visual/robotiq_85_inner_knuckle_link.obj"/>
      </geometry>
    </visual>
    <collision>
      <geometry>
        <mesh filename="../meshes/collision/robotiq_85_inner_knuckle_link.obj"/>
      </geometry>
    </collision>
    <inertial>
      <mass value="0.029951"/>
      <origin xyz="0.0 0.0 0.0"/>
      <inertia ixx="0.000039" ixy="0.000000" ixz="0.000000" iyx="0.000000" iyy="0.000005" iyz="0.000000" izx="0.000000" izy="0.000000" izz="0.000035"/>
    </inertial>
  </link>
  <joint name="robotiq_85_left_finger_tip_joint" type="continuous">
    <parent link="robotiq_85_left_inner_knuckle_link"/>
    <child link="robotiq_85_left_finger_tip_link"/>
    <axis xyz="0 0 1"/>
    <origin rpy="0.0 0.0 0.0" xyz="0.04303959807 -0.03759940821 0.0"/>
    <limit effort="0.1" lower="-3.14" upper="3.14" velocity="100.0"/>
    <mimic joint="robotiq_85_left_knuckle_joint" multiplier="-1"/>
  </joint>
  <joint name="robotiq_85_right_finger_tip_joint" type="continuous">
    <parent link="robotiq_85_right_inner_knuckle_link"/>
    <child link="robotiq_85_right_finger_tip_link"/>
    <axis xyz="0 0 1"/>
    <origin rpy="0.0 0.0 0.0" xyz="0.04303959807 -0.03759940821  0.0"/>
    <limit effort="0.1" lower="-3.14" upper="3.14" velocity="100.0"/>
    <mimic joint="robotiq_85_left_knuckle_joint" multiplier="-1"/>
  </joint>
  <link name="robotiq_85_left_finger_tip_link">
    <visual>
      <geometry>
        <mesh filename="../meshes/visual/robotiq_85_finger_tip_link.obj"/>
      </geometry>
    </visual>
    <collision>
      <geometry>
        <mesh filename="../meshes/collision/robotiq_85_finger_tip_link.obj"/>
      </geometry>
    </collision>
    <inertial>
      <mass value="0.019555"/>
      <origin xyz="0.0 0.0 0.0"/>
      <inertia ixx="0.000002" ixy="0.000000" ixz="0.000000" iyx="0.000000" iyy="0.000005" iyz="0.000000" izx="0.000000" izy="0.000000" izz="0.000006"/>
    </inertial>
  </link>
  <link name="robotiq_85_right_finger_tip_link">
    <visual>
      <geometry>
        <mesh filename="../meshes/visual/robotiq_85_finger_tip_link.obj"/>
      </geometry>
    </visual>
    <collision>
      <geometry>
        <mesh filename="../meshes/collision/robotiq_85_finger_tip_link.obj"/>
      </geometry>
    </collision>
    <inertial>
      <mass value="0.019555"/>
      <origin xyz="0.0 0.0 0.0"/>
      <inertia ixx="0.000002" ixy="0.000000" ixz="0.000000" iyx="0.000000" iyy="0.000005" iyz="0.000000" izx="0.000000" izy="0.000000" izz="0.000006"/>
    </inertial>
  </link>
  <!-- Improve grasping physics -->
  <gazebo reference="robotiq_85_left_finger_tip_link">
    <kp>1000000.0</kp>
    <kd>1.0</kd>
    <mu1>1.0</mu1>
    <mu2>1.0</mu2>
    <minDepth>0.001</minDepth>
  </gazebo>
  <gazebo reference="robotiq_85_right_finger_tip_link">
    <kp>1000000.0</kp>
    <kd>1.0</kd>
    <mu1>1.0</mu1>
    <mu2>1.0</mu2>
    <minDepth>0.001</minDepth>
  </gazebo>
  <transmission name="robotiq_85_left_knuckle_trans">
    <type>transmission_interface/SimpleTransmission</type>
    <joint name="robotiq_85_left_knuckle_joint">
      <hardwareInterface>hardware_interface/PositionJointInterface</hardwareInterface>
    </joint>
    <actuator name="robotiq_85_left_knuckle_motor">
      <mechanicalReduction>1</mechanicalReduction>
      <hardwareInterface>hardware_interface/PositionJointInterface</hardwareInterface>
    </actuator>
  </transmission>
  <!-- Mimic joints -->
  <gazebo>
    <plugin filename="libgazebo_mimic_joint_plugin.so" name="mimic_robotiq_85_1">
      <joint>robotiq_85_left_knuckle_joint</joint>
      <mimicJoint>robotiq_85_right_knuckle_joint</mimicJoint>
    </plugin>
    <plugin filename="libgazebo_mimic_joint_plugin.so" name="mimic_robotiq_85_2">
      <joint>robotiq_85_left_knuckle_joint</joint>
      <mimicJoint>robotiq_85_left_inner_knuckle_joint</mimicJoint>
    </plugin>
    <plugin filename="libgazebo_mimic_joint_plugin.so" name="mimic_robotiq_85_3">
      <joint>robotiq_85_left_knuckle_joint</joint>
      <mimicJoint>robotiq_85_right_inner_knuckle_joint</mimicJoint>
    </plugin>
    <plugin filename="libgazebo_mimic_joint_plugin.so" name="mimic_robotiq_85_4">
      <joint>robotiq_85_left_knuckle_joint</joint>
      <mimicJoint>robotiq_85_left_finger_tip_joint</mimicJoint>
      <multiplier>-1.0</multiplier>
      <offset>0.0</offset>
    </plugin>
    <plugin filename="libgazebo_mimic_joint_plugin.so" name="mimic_robotiq_85_5">
      <joint>robotiq_85_left_knuckle_joint</joint>
      <mimicJoint>robotiq_85_right_finger_tip_joint</mimicJoint>
      <multiplier>-1.0</multiplier>
      <offset>0.0</offset>
    </plugin>
  </gazebo>
</robot>
