<?xml version="1.0" ?>
<robot name="robotiq_85_gripper">
  <link name="robotiq_85_base_link">
    <visual>
      <geometry>
          <mesh filename="../meshes/visual/robotiq_85_base_link.obj"/>
      </geometry>
    </visual>
    <collision>
      <geometry>
        <mesh filename="../meshes/collision/robotiq_85_base_link.obj"/>
      </geometry>
      <drake:proximity_properties>
        <drake:rigid_hydroelastic/>
        <drake:hunt_crossley_dissipation value="1.25"/>
      </drake:proximity_properties>
    </collision>
    <inertial>
      <mass value="0.636951"/>
      <origin xyz="0.0 0.0 0.0"/>
      <inertia ixx="0.000380" ixy="0.000000" ixz="0.000000" iyx="0.000000" iyy="0.001110" iyz="0.000000" izx="0.000000" izy="0.000000" izz="0.001171"/>
    </inertial>
  </link>
  <joint name="robotiq_85_left_knuckle_joint" type="revolute">
    <parent link="robotiq_85_base_link"/>
    <child link="robotiq_85_left_knuckle_link"/>
    <axis xyz="0 0 1"/>
    <origin rpy="3.141592653589793 0.0 0.0" xyz="0.05490451627 0.03060114443 0.0"/>
    <limit effort="1000" lower="0.0" upper="0.80285" velocity="0.5"/>
  </joint>
  <joint name="robotiq_85_right_knuckle_joint" type="continuous">
    <parent link="robotiq_85_base_link"/>
    <child link="robotiq_85_right_knuckle_link"/>
    <axis xyz="0 0 1"/>
    <origin rpy="0.0 0.0 0.0" xyz="0.05490451627 -0.03060114443 0.0"/>
    <limit effort="1000" lower="0.0" upper="0.80285" velocity="0.5"/>
    <mimic joint="robotiq_85_left_knuckle_joint"/>
  </joint>
  <link name="robotiq_85_left_knuckle_link">
    <visual>
      <geometry>
        <mesh filename="../meshes/visual/robotiq_85_knuckle_link.obj"/>
      </geometry>
    </visual>
    <collision>
      <geometry>
        <mesh filename="../meshes/collision/robotiq_85_knuckle_link.obj"/>
      </geometry>
      <drake:proximity_properties>
        <drake:rigid_hydroelastic/>
        <drake:hunt_crossley_dissipation value="1.25"/>
      </drake:proximity_properties>
    </collision>
    <inertial>
      <mass value="0.018491"/>
      <origin xyz="0.0 0.0 0.0"/>
      <inertia ixx="0.000009" ixy="-0.000001" ixz="0.000000" iyx="-0.000001" iyy="0.000001" iyz="0.000000" izx="0.000000" izy="0.000000" izz="0.000010"/>
    </inertial>
  </link>
  <link name="robotiq_85_right_knuckle_link">
    <visual>
      <geometry>
        <mesh filename="../meshes/visual/robotiq_85_knuckle_link.obj"/>
      </geometry>
    </visual>
    <collision>
      <geometry>
        <mesh filename="../meshes/collision/robotiq_85_knuckle_link.obj"/>
      </geometry>
      <drake:proximity_properties>
        <drake:rigid_hydroelastic/>
        <drake:hunt_crossley_dissipation value="1.25"/>
      </drake:proximity_properties>
    </collision>
    <inertial>
      <mass value="0.018491"/>
      <origin xyz="0.0 0.0 0.0"/>
      <inertia ixx="0.000009" ixy="-0.000001" ixz="0.000000" iyx="-0.000001" iyy="0.000001" iyz="0.000000" izx="0.000000" izy="0.000000" izz="0.000010"/>
    </inertial>
  </link>
  <joint name="robotiq_85_left_finger_joint" type="fixed">
    <parent link="robotiq_85_left_knuckle_link"/>
    <child link="robotiq_85_left_finger_link"/>
    <origin rpy="0 0 0" xyz="-0.00408552455 -0.03148604435 0.0"/>
  </joint>
  <joint name="robotiq_85_right_finger_joint" type="fixed">
    <parent link="robotiq_85_right_knuckle_link"/>
    <child link="robotiq_85_right_finger_link"/>
    <origin rpy="0 0 0" xyz="-0.00408552455 -0.03148604435 0.0"/>
  </joint>
  <link name="robotiq_85_left_finger_link">
    <visual>
      <geometry>
        <mesh filename="../meshes/visual/robotiq_85_finger_link.obj"/>
      </geometry>
    </visual>
    <collision>
      <geometry>
        <mesh filename="../meshes/collision/robotiq_85_finger_link.obj"/>
      </geometry>
      <drake:proximity_properties>
        <drake:rigid_hydroelastic/>
        <drake:hunt_crossley_dissipation value="1.25"/>
      </drake:proximity_properties>
    </collision>
    <inertial>
      <mass value="0.027309"/>
      <origin xyz="0.0 0.0 0.0"/>
      <inertia ixx="0.000003" ixy="-0.000002" ixz="0.000000" iyx="-0.000002" iyy="0.000021" iyz="0.000000" izx="0.000000" izy="0.000000" izz="0.000020"/>
    </inertial>
  </link>
  <link name="robotiq_85_right_finger_link">
    <visual>
      <geometry>
        <mesh filename="../meshes/visual/robotiq_85_finger_link.obj"/>
      </geometry>
    </visual>
    <collision>
      <geometry>
        <mesh filename="../meshes/collision/robotiq_85_finger_link.obj"/>
      </geometry>
      <drake:proximity_properties>
        <drake:rigid_hydroelastic/>
        <drake:hunt_crossley_dissipation value="1.25"/>
      </drake:proximity_properties>
    </collision>
    <inertial>
      <mass value="0.027309"/>
      <origin xyz="0.0 0.0 0.0"/>
      <inertia ixx="0.000003" ixy="-0.000002" ixz="0.000000" iyx="-0.000002" iyy="0.000021" iyz="0.000000" izx="0.000000" izy="0.000000" izz="0.000020"/>
    </inertial>
  </link>
  <joint name="robotiq_85_left_inner_knuckle_joint" type="continuous">
    <parent link="robotiq_85_base_link"/>
    <child link="robotiq_85_left_inner_knuckle_link"/>
    <axis xyz="0 0 1"/>
    <origin rpy="3.141592653589793 0.0 0.0" xyz="0.06142 0.0127 0"/>
    <limit effort="0.1" lower="-3.14" upper="3.14" velocity="100.0"/>
    <mimic joint="robotiq_85_left_knuckle_joint" offset="0"/>
  </joint>
  <joint name="robotiq_85_right_inner_knuckle_joint" type="continuous">
    <parent link="robotiq_85_base_link"/>
    <child link="robotiq_85_right_inner_knuckle_link"/>
    <axis xyz="0 0 1"/>
    <origin rpy="0 0 0" xyz="0.06142 -0.0127 0"/>
    <limit effort="0.1" lower="-3.14" upper="3.14" velocity="100.0"/>
    <mimic joint="robotiq_85_left_knuckle_joint" offset="0"/>
  </joint>
  <link name="robotiq_85_left_inner_knuckle_link">
    <visual>
      <geometry>
        <mesh filename="../meshes/visual/robotiq_85_inner_knuckle_link.obj"/>
      </geometry>
    </visual>
    <collision>
      <geometry>
        <mesh filename="../meshes/collision/robotiq_85_inner_knuckle_link.obj"/>
      </geometry>
      <drake:proximity_properties>
        <drake:rigid_hydroelastic/>
        <drake:hunt_crossley_dissipation value="1.25"/>
      </drake:proximity_properties>
    </collision>
    <inertial>
      <mass value="0.029951"/>
      <origin xyz="0.0 0.0 0.0"/>
      <inertia ixx="0.000039" ixy="0.000000" ixz="0.000000" iyx="0.000000" iyy="0.000005" iyz="0.000000" izx="0.000000" izy="0.000000" izz="0.000035"/>
    </inertial>
  </link>
  <link name="robotiq_85_right_inner_knuckle_link">
    <visual>
      <geometry>
        <mesh filename="../meshes/visual/robotiq_85_inner_knuckle_link.obj"/>
      </geometry>
    </visual>
    <collision>
      <geometry>
        <mesh filename="../meshes/collision/robotiq_85_inner_knuckle_link.obj"/>
      </geometry>
      <drake:proximity_properties>
        <drake:rigid_hydroelastic/>
        <drake:hunt_crossley_dissipation value="1.25"/>
      </drake:proximity_properties>
    </collision>
    <inertial>
      <mass value="0.029951"/>
      <origin xyz="0.0 0.0 0.0"/>
      <inertia ixx="0.000039" ixy="0.000000" ixz="0.000000" iyx="0.000000" iyy="0.000005" iyz="0.000000" izx="0.000000" izy="0.000000" izz="0.000035"/>
    </inertial>
  </link>
  <joint name="robotiq_85_left_finger_tip_joint" type="continuous">
    <parent link="robotiq_85_left_inner_knuckle_link"/>
    <child link="robotiq_85_left_finger_tip_link"/>
    <axis xyz="0 0 1"/>
    <origin rpy="0.0 0.0 0.0" xyz="0.04303959807 -0.03759940821 0.0"/>
    <limit effort="0.1" lower="-3.14" upper="3.14" velocity="100.0"/>
    <mimic joint="robotiq_85_left_knuckle_joint" multiplier="-1"/>
  </joint>
  <joint name="robotiq_85_right_finger_tip_joint" type="continuous">
    <parent link="robotiq_85_right_inner_knuckle_link"/>
    <child link="robotiq_85_right_finger_tip_link"/>
    <axis xyz="0 0 1"/>
    <origin rpy="0.0 0.0 0.0" xyz="0.04303959807 -0.03759940821  0.0"/>
    <limit effort="0.1" lower="-3.14" upper="3.14" velocity="100.0"/>
    <mimic joint="robotiq_85_left_knuckle_joint" multiplier="-1"/>
  </joint>
  <link name="robotiq_85_left_finger_tip_link">
    <visual>
      <geometry>
        <mesh filename="../meshes/visual/robotiq_85_finger_tip_link.obj"/>
      </geometry>
    </visual>
    <collision>
      <geometry>
        <mesh filename="../meshes/collision/robotiq_85_finger_tip_link.obj"/>
      </geometry>
      <drake:proximity_properties>
        <drake:rigid_hydroelastic/>
        <drake:hunt_crossley_dissipation value="1.25"/>
      </drake:proximity_properties>
    </collision>
    <inertial>
      <mass value="0.019555"/>
      <origin xyz="0.0 0.0 0.0"/>
      <inertia ixx="0.000002" ixy="0.000000" ixz="0.000000" iyx="0.000000" iyy="0.000005" iyz="0.000000" izx="0.000000" izy="0.000000" izz="0.000006"/>
    </inertial>
  </link>
  <link name="robotiq_85_right_finger_tip_link">
    <visual>
      <geometry>
        <mesh filename="../meshes/visual/robotiq_85_finger_tip_link.obj"/>
      </geometry>
    </visual>
    <collision>
      <geometry>
        <mesh filename="../meshes/collision/robotiq_85_finger_tip_link.obj"/>
      </geometry>
      <drake:proximity_properties>
        <drake:rigid_hydroelastic/>
        <drake:hunt_crossley_dissipation value="1.25"/>
      </drake:proximity_properties>
    </collision>
    <inertial>
      <mass value="0.019555"/>
      <origin xyz="0.0 0.0 0.0"/>
      <inertia ixx="0.000002" ixy="0.000000" ixz="0.000000" iyx="0.000000" iyy="0.000005" iyz="0.000000" izx="0.000000" izy="0.000000" izz="0.000006"/>
    </inertial>
  </link>

  <!-- Bushings for modeling closed-loop linkage -->
  <frame name="left_bushing_frame_A" link="robotiq_85_left_finger_link" rpy="0 0 0" xyz="0.0472 -0.0061 0"/>
  <frame name="left_bushing_frame_B" link="robotiq_85_left_finger_tip_link" rpy="0 0 0" xyz="-0.00645 -0.01788 0"/>
  <frame name="right_bushing_frame_A" link="robotiq_85_right_finger_link" rpy="0 0 0" xyz="0.0472 -0.0061 0"/>
  <frame name="right_bushing_frame_B" link="robotiq_85_right_finger_tip_link" rpy="0 0 0" xyz="-0.00645 -0.01788 0"/>

  <!-- DEBUG -->
  <!--
  <link name="left_bushing_A">
    <visual>
      <geometry>
        <box size="0.0001 0.0001 0.1"/>
      </geometry>
      <material>
        <color rgba="1 0 0 1"/>
      </material>
    </visual>
  </link>
  <joint name="test_A" type="fixed">
    <parent link="robotiq_85_left_finger_link"/>
    <child link="left_bushing_A"/>
    <origin rpy="0.0 0.0 0.0" xyz="0.0472 -0.0061 0.0"/>
  </joint>
  <link name="left_bushing_B">
    <visual>
      <geometry>
        <box size="0.0001 0.0001 0.1"/>
      </geometry>
    </visual>
  </link>
  <joint name="test_B" type="fixed">
    <parent link="robotiq_85_left_finger_tip_link"/>
    <child link="left_bushing_B"/>
    <origin rpy="0.0 0.0 0.0" xyz="-0.00645 -0.01788 0.0"/>
  </joint>
  -->

  <drake:linear_bushing_rpy>
    <drake:bushing_frameA name="left_bushing_frame_A"/>
    <drake:bushing_frameC name="left_bushing_frame_B"/>
    <drake:bushing_torque_stiffness value="20 20 0"/>
    <drake:bushing_torque_damping value="2 2 0"/>
    <drake:bushing_force_stiffness value="20 20 20"/>
    <drake:bushing_force_damping value="2 2 2"/>
  </drake:linear_bushing_rpy>
  <drake:linear_bushing_rpy>
    <drake:bushing_frameA name="right_bushing_frame_A"/>
    <drake:bushing_frameC name="right_bushing_frame_B"/>
    <drake:bushing_torque_stiffness value="20 20 0"/>
    <drake:bushing_torque_damping value="2 2 0"/>
    <drake:bushing_force_stiffness value="20 20 20"/>
    <drake:bushing_force_damping value="2 2 2"/>
  </drake:linear_bushing_rpy>


  <transmission name="robotiq_85_left_knuckle_trans">
    <type>transmission_interface/SimpleTransmission</type>
    <joint name="robotiq_85_left_knuckle_joint">
      <hardwareInterface>hardware_interface/PositionJointInterface</hardwareInterface>
    </joint>
    <actuator name="robotiq_85_left_knuckle_motor">
      <mechanicalReduction>1</mechanicalReduction>
      <hardwareInterface>hardware_interface/PositionJointInterface</hardwareInterface>
    </actuator>
  </transmission>
  <transmission name="robotiq_85_right_knuckle_trans">
    <type>transmission_interface/SimpleTransmission</type>
    <joint name="robotiq_85_right_knuckle_joint">
      <hardwareInterface>hardware_interface/PositionJointInterface</hardwareInterface>
    </joint>
    <actuator name="robotiq_85_right_knuckle_motor">
      <mechanicalReduction>1</mechanicalReduction>
      <hardwareInterface>hardware_interface/PositionJointInterface</hardwareInterface>
    </actuator>
  </transmission>
  <drake:collision_filter_group name="self">
    <drake:member link="robotiq_85_base_link"/>
    <drake:member link="robotiq_85_left_knuckle_link"/>
    <drake:member link="robotiq_85_left_inner_knuckle_link"/>
    <drake:member link="robotiq_85_left_finger_link"/>
    <drake:member link="robotiq_85_left_finger_tip_link"/>
    <drake:member link="robotiq_85_right_knuckle_link"/>
    <drake:member link="robotiq_85_right_inner_knuckle_link"/>
    <drake:member link="robotiq_85_right_finger_link"/>
    <drake:member link="robotiq_85_right_finger_tip_link"/>
    <drake:ignored_collision_filter_group name="self"/>
  </drake:collision_filter_group>
</robot>
